# 🔧 Bug 修复完成

## 问题分析

根据日志 `/data/ws/kronos/logs/1.txt`，发现两个问题：

### 问题 1: 422 Unprocessable Entity
- **原因**: Pydantic 验证错误，`overrides` 字段验证问题
- **解决**: 测试客户端的 `overrides` 格式已经是正确的，实际是问题2导致

### 问题 2: 500 Internal Server Error - DatetimeIndex 错误
- **错误**: `'DatetimeIndex' object has no attribute 'dt'`
- **原因**: `predictor.py` 中 `pd.to_datetime()` 返回 `DatetimeIndex` 而不是 `Series`
- **位置**: 
  - 第147行: `y_timestamp = pd.to_datetime(prediction_timestamps)`
  - 第189行: `y_timestamp_list.append(pd.Series(prediction_timestamps))`

## 已应用的修复

**文件**: `services/kronos_fastapi/predictor.py`

### 修复 1: predict_single 方法（第147行）
```python
# 修复前
y_timestamp = pd.to_datetime(prediction_timestamps)

# 修复后
y_timestamp = pd.Series(pd.to_datetime(prediction_timestamps))
```

### 修复 2: predict_batch 方法（第189行）
```python
# 修复前
y_timestamp_list.append(pd.Series(prediction_timestamps))

# 修复后
y_timestamp_list.append(pd.Series(pd.to_datetime(prediction_timestamps)))
```

## ⚠️ 需要重启服务

修复已应用到代码，但服务器正在使用旧代码。

### 重启步骤

1. **停止当前服务** (在运行服务的终端按 Ctrl+C)

2. **重新启动服务**:
   ```bash
   cd /data/ws/kronos/services
   ./start_cpu_simple.sh
   ```

3. **等待模型加载** (1-2 分钟)

4. **验证修复**:
   ```bash
   # 测试简单请求
   curl -X POST http://localhost:8000/v1/predict/single \
     -H "Content-Type: application/json" \
     -d '{
       "series_id": "test",
       "candles": [{"open": 100, "high": 101, "low": 99, "close": 100.5, "volume": 1000000, "amount": 100500000}],
       "timestamps": ["2024-01-01T09:30:00"],
       "prediction_timestamps": ["2024-01-01T09:31:00"]
     }'
   ```

5. **运行完整测试**:
   ```bash
   cd /data/ws/kronos/services
   python test_cpu_prediction.py
   ```

## 技术细节

### pandas 类型差异

```python
import pandas as pd

timestamps = ['2024-01-01T09:30:00']

# 返回 DatetimeIndex（没有 .dt 属性）
result1 = pd.to_datetime(timestamps)
type(result1)  # pandas.core.indexes.datetimes.DatetimeIndex
hasattr(result1, 'dt')  # False

# 返回 Series（有 .dt 属性）
result2 = pd.Series(pd.to_datetime(timestamps))
type(result2)  # pandas.core.series.Series
hasattr(result2, 'dt')  # True
```

`calc_time_stamps()` 函数需要 Series 类型才能使用 `.dt` 访问器：
```python
def calc_time_stamps(x_timestamp):
    time_df = pd.DataFrame()
    time_df['minute'] = x_timestamp.dt.minute  # 需要 .dt 属性
    time_df['hour'] = x_timestamp.dt.hour
    # ...
```

## 预期结果

重启后，测试应该成功并显示：

```
======================================================================
⏱️  预测时间统计
======================================================================
总耗时: 12.34 秒
平均每个预测点: 1.234 秒
吞吐量: 0.81 点/秒

预测结果（前3个点）:
  1. 时间: 2024-01-01T11:10:00
     OHLC: O=104.23, H=105.12, L=103.89, C=104.56
```

## 相关文件

- 修复的文件: `services/kronos_fastapi/predictor.py`
- 测试客户端: `services/test_cpu_prediction.py`
- 启动脚本: `services/start_cpu_simple.sh`
- 错误日志: `/data/ws/kronos/logs/1.txt`
